<?xml version="1.0" ?>
<sdf version="1.9">
  <model name="box_motor_drone">
    <static>false</static>
    <pose>0 0 0.3 0 0 0</pose>

    <!-- Base box body -->
    <link name="base_link">
      <pose>0 0 0 0 0 0</pose>
      <inertial>
        <mass>10.0</mass>
        <inertia>
          <ixx>0.1</ixx>
          <iyy>0.1</iyy>
          <izz>0.1</izz>
        </inertia>
      </inertial>
      <collision name="base_collision">
        <geometry>
          <box>
            <size>0.2 0.2 0.1</size>
          </box>
        </geometry>
      </collision>
      <visual name="base_visual">
        <geometry>
          <box>
            <size>0.2 0.2 0.1</size>
          </box>
        </geometry>
      </visual>
    </link>

    <!-- Rotor with elliptical visual -->
    <link name="rotor_0">
      <pose>0 0 0.1 0 0 0</pose>
      <inertial>
        <mass>0.05</mass>
        <inertia>
          <ixx>1e-5</ixx>
          <iyy>1e-5</iyy>
          <izz>2e-5</izz>
        </inertia>
      </inertial>
      <collision name="rotor_collision">
        <geometry>
          <box>
            <size>0.3 0.05 0.01</size>
          </box>
        </geometry>
      </collision>
      <visual name="rotor_visual">
        <geometry>
          <box>
            <size>0.3 0.05 0.01</size>  <!-- Elliptical-like shape -->
          </box>
        </geometry>
        <material>
          <ambient>0.1 0.1 0.1 1</ambient>
          <diffuse>0.2 0.2 0.2 1</diffuse>
        </material>
      </visual>
    </link>

    <joint name="rotor_0_joint" type="revolute">
      <parent>base_link</parent>
      <child>rotor_0</child>
      <axis>
        <xyz>0 0 1</xyz>
        <limit>
          <lower>-1e16</lower>
          <upper>1e16</upper>
        </limit>
      </axis>
    </joint>

    <plugin name="gz::sim::systems::MulticopterMotorModel" filename="gz-sim-multicopter-motor-model-system">
      <jointName>rotor_0_joint</jointName>
      <linkName>rotor_0</linkName>
      <turningDirection>ccw</turningDirection>
      <timeConstantUp>0.01</timeConstantUp>
      <timeConstantDown>0.02</timeConstantDown>
      <maxRotVelocity>2000</maxRotVelocity>
      <motorConstant>1e-5</motorConstant>
      <momentConstant>0.02</momentConstant>
      <commandSubTopic>command/motor_speed</commandSubTopic>
      <motorNumber>0</motorNumber>
      <rotorDragCoefficient>1e-5</rotorDragCoefficient>
      <rollingMomentCoefficient>1e-6</rollingMomentCoefficient>
      <rotorVelocitySlowdownSim>10</rotorVelocitySlowdownSim>
      <motorType>velocity</motorType>
    </plugin>
  </model>
</sdf>
